Workbook

Sheet PORCENTAJES
A1: LA PAZ PLANILLA PARA CALCULO DE DESCUENTO E INCREMENTO | F1: Menos % comision del mèdico
A2: CLAVE | B2: ESTUDIO | C2: AREA | D2: %% | E2: PRECIO PARTICULAR | F2: PRECIO SIN COMISION MEDICO
A3: 1-3bD | B3: (1-3)-B-D-Glucano | C3: Inmunologia | D3: 0.1 | E3: =VLOOKUP(A3,'PRE PART LPZ'!A:D,4,0) -> 0 | F3: =+E3-(E3*D3) -> 0
A4: 17OHP | B4: 17-OH PROGESTERONA | C4: Endocrinologia | D4: 0.1 | E4: =VLOOKUP(A4,'PRE PART LPZ'!A:D,4,0) -> 292 | F4: =+E4-(E4*D4) -> 262.8
A5: 5NT | B5: 5 - NUCLEOTIDASA | C5: Química Metabólica | D5: 0.1 | E5: =VLOOKUP(A5,'PRE PART LPZ'!A:D,4,0) -> 0 | F5: =+E5-(E5*D5) -> 0
A6: CCP | B6: AC. ANTICITRULINA (Anti-CCP) | C6: Autoinmunidad | D6: 0.1 | E6: =VLOOKUP(A6,'PRE PART LPZ'!A:D,4,0) -> 302 | F6: =+E6-(E6*D6) -> 271.8
A7: Es1852 | B7: AC. ANTICITRULINA Anti-CCP (FIA) | C7: Inmunología | D7: 0.1 | E7: =VLOOKUP(A7,'PRE PART LPZ'!A:D,4,0) -> 0 | F7: =+E7-(E7*D7) -> 0
A8: 5-HIAA | B8: ÁCIDO 5-HIDROXIINDOLACÉTICO | C8: Inmunología | D8: 0.1 | E8: =VLOOKUP(A8,'PRE PART LPZ'!A:D,4,0) -> 0 | F8: =+E8-(E8*D8) -> 0
A9: AcFol | B9: ÁCIDO FÓLICO | C9: Química Metabólica | D9: 0.15 | E9: =VLOOKUP(A9,'PRE PART LPZ'!A:D,4,0) -> 277 | F9: =+E9-(E9*D9) -> 235.45
A10: AcUr | B10: ÁCIDO ÚRICO | C10: Química Metabólica | D10: 0.3 | E10: =VLOOKUP(A10,'PRE PART LPZ'!A:D,4,0) -> 52 | F10: =+E10-(E10*D10) -> 36.4
A11: AcUr24 | B11: ÁCIDO ÚRICO EN ORINA 24 HORAS | C11: Orinas | D11: 0.3 | E11: =VLOOKUP(A11,'PRE PART LPZ'!A:D,4,0) -> 47 | F11: =+E11-(E11*D11) -> 32.9
A12: AcUrOr | B12: ÁCIDO ÚRICO EN ORINA OCASIONAL | C12: Orinas | D12: 0.3 | E12: =VLOOKUP(A12,'PRE PART LPZ'!A:D,4,0) -> 47 | F12: =+E12-(E12*D12) -> 32.9
A13: VPA | B13: ÁCIDO VALPROICO | C13: Toxicología Terapeútica | D13: 0.1 | E13: =VLOOKUP(A13,'PRE PART LPZ'!A:D,4,0) -> 0 | F13: =+E13-(E13*D13) -> 0
A14: Es1828 | B14: ACIDOS BILIARES | C14: Análisis de Orina | D14: 0.1 | E14: =VLOOKUP(A14,'PRE PART LPZ'!A:D,4,0) -> 0 | F14: =+E14-(E14*D14) -> 0
... A633: Zn | B633: ZINC (Zn) | C633: Química Metabólica | D633: 0.1 | E633: =VLOOKUP(A633,'PRE PART LPZ'!A:D,4,0) -> 0 | F633: =+E633-(E633*D633) -> 0

Sheet PRE PART LPZ
A1: CLAVE | B1: ESTUDIO | C1: DEPARTAMENTO | D1: PRECIO PARTICULAR LPZ
A2: CU147 | C2: Análisis de Orina | D2: 0
A3: 1-3bD | B3: (1-3)-B-D-GLUCANO | C3: Infecciosas | D3: 0
A4: 17OHP | B4: 17-OH PROGESTERONA | C4: Inmunología | D4: 292
A5: 5NT | B5: 5 - NUCLEOTIDASA | C5: Química Metabólica | D5: 0
A6: CCP | B6: AC. ANTICITRULINA (Anti-CCP) | C6: Inmunología | D6: 302
A7: Es1852 | B7: AC. ANTICITRULINA Anti-CCP (FIA) | C7: Inmunología | D7: 0
A8: 5-HIAA | B8: ÁCIDO 5-HIDROXIINDOLACÉTICO | C8: Inmunología | D8: 0
A9: AcFol | B9: ÁCIDO FÓLICO | C9: Inmunología | D9: 277
A10: AcUr | B10: ÁCIDO ÚRICO | C10: Química Metabólica | D10: 52
A11: AcUr24 | B11: ÁCIDO ÚRICO EN ORINA 24 HORAS | C11: Análisis de Orina | D11: 47
A12: AcUrOr | B12: ÁCIDO ÚRICO EN ORINA OCASIONAL | C12: Análisis de Orina | D12: 47
A13: VPA | B13: ÁCIDO VALPROICO | C13: Inmunología | D13: 0
A14: Es1828 | B14: ACIDOS BILIARES | C14: Análisis de Orina | D14: 0
... A191: GDH | B191: CLOSTRIDIUM DIFFICILE TOXINAS A/B | C191: Coprología | D191: 272
A192: Es1864 | B192: COAGULOGRAMA (TP | C192: APTT | D192: T, de Coagulación
A193: COC | B193: COCAÍNA SCREEN | C193: Análisis de Orina | D193: 0
A194: MxQFT | B194: COLECTOR - QuantiFERON TB | C194: Inmunología | D194: 702
A195: Col | B195: COLESTEROL | C195: Química Metabólica | D195: 58
A196: CHE | B196: COLINESTERASA | C196: Química Metabólica | D196: 92
A197: Es1837 | B197: COLISTINA | C197: Microbiología | D197: 0
A198: C3 | B198: COMPLEMENTO C3 | C198: Inmunología | D198: 0
A199: Es1904 | B199: COMPLEMENTO C3 (t) | C199: Inmunología | D199: 132
A200: C4 | B200: COMPLEMENTO C4 | C200: Inmunología | D200: 0
A201: Es1905 | B201: COMPLEMENTO C4 (t) | C201: Inmunología | D201: 132
A202: CH50 | B202: COMPLEMENTO HEMOLITICO (CH50) | C202: Inmunología | D202: 0
A203: CDir | B203: COOMBS DIRECTO | C203: Hematología | D203: 73
A204: CInd | B204: COOMBS INDIRECTO | C204: Hematología | D204: 73
... A258: Deng | B258: DENGUE IgG/IgM/NS1 | C258: Serologia y Pruebas Rapidas | D258: 163
A259: PR-DZC | B259: DENGUE | C259: ZIKA | D259: CHIKUNGUNYA - PRUEBA RÁPIDA
A260: DepCre | B260: DEPURACIÓN DE CREATININA | C260: Análisis de Orina | D260: 73
A261: DHEA | B261: DESHIDROEPIANDROSTENA (DHEA) | C261: Inmunología | D261: 0
A262: DheS | B262: DHEA-S | C262: Inmunología | D262: 303
A263: DHT | B263: DIHIDROTESTOSTERONA (DHT) | C263: Inmunología | D263: 0
A264: DimD | B264: DÍMERO D (a) | C264: Inmunología | D264: 0
A265: Es1845 | B265: DÍMERO D (FIA) | C265: Hematología | D265: 300
A266: DDPr | B266: DIMERO D - PRUEBA RÁPIDA | C266: Serologia y Pruebas Rapidas | D266: 0
A267: DSem | B267: DIRECTO DE LIQUIDO SEMINAL | C267: Estudio de Líquidos Biológicos | D267: 0
A268: DisEr | B268: DISMORFISMO ERITROCITARIO | C268: Análisis de Orina | D268: 0
A269: Es1827 | B269: DOSIFICACIÓN DE ERITROPOYETINA | C269: Hematología | D269: 0
...
